Workbook

Sheet الحركة اليومية
A2: المبيعات اليومية عن عام 2026 لمعرض
A4: التاريخ | B4: اليوم | C4: رصيد الصندوق في بداية اليوم | D4: المبيعات النقدية | E4: مبيعات الشبكة | L4: اجمالي المبيعات | M4: الايداعات | N4: الشبكة | O4: مسحوبات غير نقدية | P4: المصاريف معمدة من الادارة | Q4: رصيد الصندوق في نهاية اليوم | R4: رقم تسلسل الايداع | S4: ملاحظات
E5: الشبكة السعودية | F5: الفيزا | G5: الماستر كارد | H5: الامريكانا اكسبريس | I5: كوبونات الجمعيات | J5: تمارا | K5: مبيعات اخرى
A6: 46023 | B6: الخميس | C6: 0 | D6: 1442.4 | E6: 5984 | G6: 388 | J6: 498 | L6: =SUM(D6:K6) -> 8312.4 | N6: =SUM(E6+F6+G6+H6) -> 6372 | O6: =I6+K6+J6 -> 498 | Q6: =C6+L6+-M6-N6-O6-P6 -> 1442.4
A7: =A6+1 -> 46024 | B7: الجمعه | C7: =Q6 -> 1442.4 | D7: 15 | E7: 3962 | F7: 983 | L7: =SUM(D7:K7) -> 4960 | N7: =SUM(E7+F7+G7+H7) -> 4945 | O7: =I7+K7+J7 -> 0 | Q7: =C7+L7+-M7-N7-O7-P7 -> 1457.4
A8: =A7+1 -> 46025 | B8: السبت | C8: =Q7 -> 1457.4 | D8: 658.2 | E8: 6028 | F8: 695 | G8: 609 | L8: =SUM(D8:K8) -> 7990.2 | N8: =SUM(E8+F8+G8+H8) -> 7332 | O8: =I8+K8+J8 -> 0 | Q8: =C8+L8+-M8-N8-O8-P8 -> 2115.6
A9: =A8+1 -> 46026 | B9: الأحد | C9: =Q8 -> 2115.6 | D9: 587 | E9: 2381.2 | F9: 99 | L9: =SUM(D9:K9) -> 3067.2 | N9: =SUM(E9+F9+G9+H9) -> 2480.2 | O9: =I9+K9+J9 -> 0 | Q9: =C9+L9+-M9-N9-O9-P9 -> 2702.6
A10: =A9+1 -> 46027 | B10: الإثنين | C10: =Q9 -> 2702.6 | D10: -51 | E10: 2335 | F10: 597 | L10: =SUM(D10:K10) -> 2881 | N10: =SUM(E10+F10+G10+H10) -> 2932 | O10: =I10+K10+J10 -> 0 | Q10: =C10+L10+-M10-N10-O10-P10 -> 2651.6
A11: =A10+1 -> 46028 | B11: الثلاثاء | C11: =Q10 -> 2651.6 | D11: 449 | E11: 3338 | F11: 199 | L11: =SUM(D11:K11) -> 3986 | N11: =SUM(E11+F11+G11+H11) -> 3537 | O11: =I11+K11+J11 -> 0 | Q11: =C11+L11+-M11-N11-O11-P11 -> 3100.6
A12: =A11+1 -> 46029 | B12: الأربعاء | C12: =Q11 -> 3100.6 | D12: 1143 | E12: 3882 | F12: 1238 | G12: 139 | J12: 406 | L12: =SUM(D12:K12) -> 6808 | N12: =SUM(E12+F12+G12+H12) -> 5259 | O12: =I12+K12+J12 -> 406 | Q12: =C12+L12+-M12-N12-O12-P12 -> 4243.6
A13: =A12+1 -> 46030 | B13: الخميس | C13: =Q12 -> 4243.6 | D13: 1362 | E13: 4405 | F13: 739 | L13: =SUM(D13:K13) -> 6506 | N13: =SUM(E13+F13+G13+H13) -> 5144 | O13: =I13+K13+J13 -> 0 | Q13: =C13+L13+-M13-N13-O13-P13 -> 5605.6
A14: =A13+1 -> 46031 | B14: الجمعه | C14: =Q13 -> 5605.6 | D14: 2499 | E14: 5367 | F14: 816 | J14: 266 | L14: =SUM(D14:K14) -> 8948 | N14: =SUM(E14+F14+G14+H14) -> 6183 | O14: =I14+K14+J14 -> 266 | Q14: =C14+L14+-M14-N14-O14-P14 -> 8104.6 | S14: إيداع رقم 1
A15: =A14+1 -> 46032 | B15: السبت | C15: =Q14 -> 8104.6 | D15: 715 | E15: 5558 | F15: 1567 | G15: 119 | L15: =SUM(D15:K15) -> 7959 | M15: 6400 | N15: =SUM(E15+F15+G15+H15) -> 7244 | O15: =I15+K15+J15 -> 0 | Q15: =C15+L15+-M15-N15-O15-P15 -> 2419.6
A16: =A15+1 -> 46033 | B16: الأحد | C16: =Q15 -> 2419.6 | D16: 622 | E16: 4264.2 | F16: 861 | G16: 513 | L16: =SUM(D16:K16) -> 6260.2 | N16: =SUM(E16+F16+G16+H16) -> 5638.2 | O16: =I16+K16+J16 -> 0 | Q16: =C16+L16+-M16-N16-O16-P16 -> 3041.6
A17: =A16+1 -> 46034 | B17: الإثنين | C17: =Q16 -> 3041.6 | D17: 1396 | E17: 8722 | F17: 656 | L17: =SUM(D17:K17) -> 10774 | N17: =SUM(E17+F17+G17+H17) -> 9378 | O17: =I17+K17+J17 -> 0 | Q17: =C17+L17+-M17-N17-O17-P17 -> 4437.6
A18: =A17+1 -> 46035 | B18: الثلاثاء | C18: =Q17 -> 4437.6 | D18: 1084.2 | E18: 4524 | F18: 353 | J18: 199 | L18: =SUM(D18:K18) -> 6160.2 | N18: =SUM(E18+F18+G18+H18) -> 4877 | O18: =I18+K18+J18 -> 199 | Q18: =C18+L18+-M18-N18-O18-P18 -> 5521.8
A19: =A18+1 -> 46036 | B19: الأربعاء | C19: =Q18 -> 5521.8 | D19: 763.2 | E19: 2404 | F19: 207 | J19: 1453 | L19: =SUM(D19:K19) -> 4827.2 | N19: =SUM(E19+F19+G19+H19) -> 2611 | O19: =I19+K19+J19 -> 1453 | Q19: =C19+L19+-M19-N19-O19-P19 -> 6285
A20: =A19+1 -> 46037 | B20: الخميس | C20: =Q19 -> 6285 | D20: 1352 | E20: 5511.2 | G20: 665 | L20: =SUM(D20:K20) -> 7528.2 | M20: 4650 | N20: =SUM(E20+F20+G20+H20) -> 6176.2 | O20: =I20+K20+J20 -> 0 | Q20: =C20+L20+-M20-N20-O20-P20 -> 2987 | S20: إيداع رقم 2
A21: =A20+1 -> 46038 | B21: الجمعه | C21: =Q20 -> 2987 | D21: 677 | E21: 4883 | L21: =SUM(D21:K21) -> 5560 | N21: =SUM(E21+F21+G21+H21) -> 4883 | O21: =I21+K21+J21 -> 0 | Q21: =C21+L21+-M21-N21-O21-P21 -> 3664
A22: =A21+1 -> 46039 | B22: السبت | C22: =Q21 -> 3664 | D22: 510 | E22: 4457 | F22: 338 | G22: 398 | H22: 22 | J22: 844 | L22: =SUM(D22:K22) -> 6569 | N22: =SUM(E22+F22+G22+H22) -> 5215 | O22: =I22+K22+J22 -> 844 | Q22: =C22+L22+-M22-N22-O22-P22 -> 4174
A23: =A22+1 -> 46040 | B23: الاحد | C23: =Q22 -> 4174 | D23: 527 | E23: 2725 | F23: 636 | G23: 78 | J23: 199 | L23: =SUM(D23:K23) -> 4165 | N23: =SUM(E23+F23+G23+H23) -> 3439 | O23: =I23+K23+J23 -> 199 | Q23: =C23+L23+-M23-N23-O23-P23 -> 4701
A24: =A23+1 -> 46041 | B24: الاثنين | C24: =Q23 -> 4701 | D24: 1413 | E24: 2066 | J24: 259 | L24: =SUM(D24:K24) -> 3738 | N24: =SUM(E24+F24+G24+H24) -> 2066 | O24: =I24+K24+J24 -> 259 | Q24: =C24+L24+-M24-N24-O24-P24 -> 6114
A25: =A24+1 -> 46042 | B25: الثلاثاء | C25: =Q24 -> 6114 | D25: 871 | E25: 2096 | F25: 217 | L25: =SUM(D25:K25) -> 3184 | N25: =SUM(E25+F25+G25+H25) -> 2313 | O25: =I25+K25+J25 -> 0 | Q25: =C25+L25+-M25-N25-O25-P25 -> 6985
A26: =A25+1 -> 46043 | B26: الاربعاء | C26: =Q25 -> 6985 | D26: 1592 | E26: 560 | F26: 346 | L26: =SUM(D26:K26) -> 2498 | N26: =SUM(E26+F26+G26+H26) -> 906 | O26: =I26+K26+J26 -> 0 | Q26: =C26+L26+-M26-N26-O26-P26 -> 8577
A27: =A26+1 -> 46044 | B27: الخميس | C27: =Q26 -> 8577 | D27: 694 | E27: 2883 | F27: 343 | L27: =SUM(D27:K27) -> 3920 | M27: 6000 | N27: =SUM(E27+F27+G27+H27) -> 3226 | O27: =I27+K27+J27 -> 0 | Q27: =C27+L27+-M27-N27-O27-P27 -> 3271 | S27: إيداع رقم 3
A28: =A27+1 -> 46045 | B28: الجمعه | C28: =Q27 -> 3271 | D28: 764 | E28: 3206 | F28: 119 | L28: =SUM(D28:K28) -> 4089 | N28: =SUM(E28+F28+G28+H28) -> 3325 | O28: =I28+K28+J28 -> 0 | Q28: =C28+L28+-M28-N28-O28-P28 -> 4035
A29: =A28+1 -> 46046 | B29: السبت | C29: =Q28 -> 4035 | D29: 249 | E29: 3168 | F29: 510 | G29: 598 | L29: =SUM(D29:K29) -> 4525 | N29: =SUM(E29+F29+G29+H29) -> 4276 | O29: =I29+K29+J29 -> 0 | Q29: =C29+L29+-M29-N29-O29-P29 -> 4284
A30: =A29+1 -> 46047 | B30: الاحد | C30: =Q29 -> 4284 | D30: 234 | E30: 1651 | F30: 551 | G30: 1124 | J30: 199 | L30: =SUM(D30:K30) -> 3759 | N30: =SUM(E30+F30+G30+H30) -> 3326 | O30: =I30+K30+J30 -> 199 | Q30: =C30+L30+-M30-N30-O30-P30 -> 4518
A31: =A30+1 -> 46048 | B31: الاثنين | C31: =Q30 -> 4518 | E31: 1412 | G31: 642 | L31: =SUM(D31:K31) -> 2054 | N31: =SUM(E31+F31+G31+H31) -> 2054 | O31: =I31+K31+J31 -> 0 | Q31: =C31+L31+-M31-N31-O31-P31 -> 4518
A32: =A31+1 -> 46049 | B32: الثلاثاء | C32: =Q31 -> 4518 | D32: 1850 | E32: 4299 | F32: 606 | G32: 189 | L32: =SUM(D32:K32) -> 6944 | N32: =SUM(E32+F32+G32+H32) -> 5094 | O32: =I32+K32+J32 -> 0 | Q32: =C32+L32+-M32-N32-O32-P32 -> 6368
A33: =A32+1 -> 46050 | B33: الأربعاء | C33: =Q32 -> 6368 | D33: 410 | E33: 6506.4 | F33: 338 | G33: 168 | L33: =SUM(D33:K33) -> 7422.4 | N33: =SUM(E33+F33+G33+H33) -> 7012.4 | O33: =I33+K33+J33 -> 0 | Q33: =C33+L33+-M33-N33-O33-P33 -> 6778
A34: =A33+1 -> 46051 | B34: الخميس | C34: =Q33 -> 6778 | D34: 358 | E34: 2124 | F34: 199 | J34: 483 | L34: =SUM(D34:K34) -> 3164 | M34: 4300 | N34: =SUM(E34+F34+G34+H34) -> 2323 | O34: =I34+K34+J34 -> 483 | Q34: =C34+L34+-M34-N34-O34-P34 -> 2836 | S34: إيداع رقم 4
A35: =A34+1 -> 46052 | B35: الجمعة | C35: =Q34 -> 2836 | D35: 596 | E35: 3689 | F35: 179 | J35: 149 | L35: =SUM(D35:K35) -> 4613 | N35: =SUM(E35+F35+G35+H35) -> 3868 | O35: =I35+K35+J35 -> 149 | Q35: =C35+L35+-M35-N35-O35-P35 -> 3432
A36: =A35+1 -> 46053 | B36: السبت | C36: =Q35 -> 3432 | D36: 1345 | E36: 5478 | F36: 1142 | J36: 149 | L36: =SUM(D36:K36) -> 8114 | N36: =SUM(E36+F36+G36+H36) -> 6620 | O36: =I36+K36+J36 -> 149 | Q36: =C36+L36+-M36-N36-O36-P36 -> 4777
D38: =SUM(D6:D36) -> 26127 | E38: =SUM(E6:E36) -> 119869 | F38: =SUM(F6:F36) -> 14534 | G38: =SUM(G6:G36) -> 5630 | H38: =SUM(H6:H36) -> 22 | I38: =SUM(I6:I36) -> 0 | J38: =SUM(J6:J36) -> 5104 | K38: =SUM(K6:K36) -> 0 | ... P38: =SUM(P6:P36) -> 0 | Q38: =C38+L38+-M38-N38-O38-P38 -> 4777
A40: التاريخ | B40: اليوم | C40: رصيد الصندوق في بداية اليوم | D40: المبيعات النقدية | E40: مبيعات الشبكة | L40: اجمالي المبيعات | M40: الايداعات | N40: الشبكة | O40: مسحوبات غير نقدية | P40: المصاريف معمدة من الادارة | Q40: رصيد الصندوق في نهاية اليوم | R40: رقم تسلسل الايداع | S40: ملاحظات
E41: الشبكة السعودية | F41: الفيزا | G41: الماستر كارد | H41: الامريكانا اكسبريس | I41: كوبونات الجمعيات | J41: تمارا | K41: مبيعات اخرى
A42: =A36+1 -> 46054 | B42: الأحد | C42: =Q38 -> 4777 | D42: -50 | E42: 2601.39 | G42: 25 | L42: =SUM(D42:K42) -> 2576.39 | N42: =SUM(E42+F42+G42+H42) -> 2626.39 | O42: =I42+K42+J42 -> 0 | Q42: =C42+L42+-M42-N42-O42-P42 -> 4727
A43: =A42+1 -> 46055 | B43: الإثنين | C43: =Q42 -> 4727 | D43: 497.2 | E43: 1620.2 | F43: 238 | L43: =SUM(D43:K43) -> 2355.4 | N43: =SUM(E43+F43+G43+H43) -> 1858.2 | O43: =I43+K43+J43 -> 0 | Q43: =C43+L43+-M43-N43-O43-P43 -> 5224.2
A44: =A43+1 -> 46056 | B44: الثلاثاء | C44: =Q43 -> 5224.2 | D44: 871 | E44: 1497.2 | F44: 984 | G44: 365 | L44: =SUM(D44:K44) -> 3717.2 | N44: =SUM(E44+F44+G44+H44) -> 2846.2 | O44: =I44+K44+J44 -> 0 | Q44: =C44+L44+-M44-N44-O44-P44 -> 6095.2
...

Sheet الحركات الشهرية
A3: الشهر | B3: رصيد الصندوق في بداية اليوم | C3: المبيعات النقدية | D3: مبيعات الشبكة | K3: اجمالي المبيعات | L3: الايداعات | M3: الشبكة | N3: مسحوبات غير نقدية | O3: المصاريف معمدة من الادارة | P3: رصيد الصندوق في نهاية اليوم | Q3: ملاحظات
D4: الشبكة السعودية | E4: الفيزا | F4: الماستر كارد | G4: الامريكانا اكسبريس | H4: كوبونات الجمعيات | I4: تمارا | J4: مبيعات اخرى
A5: يناير 2026 | B5: 0 | C5: ='الحركة اليومية'!D38 -> 26127 | D5: ='الحركة اليومية'!E38 -> 119869 | E5: ='الحركة اليومية'!F38 -> 14534 | F5: ='الحركة اليومية'!G38 -> 5630 | G5: ='الحركة اليومية'!H38 -> 22 | H5: ='الحركة اليومية'!I38 -> 0 | I5: ='الحركة اليومية'!J38 -> 5104 | J5: ='الحركة اليومية'!K38 -> 0 | ... P5: ='الحركة اليومية'!Q38 -> 4777 | Q5: ='الحركة اليومية'!S38 -> 0
A6: فبراير 2026 | B6: =P5 -> 4777 | C6: ='الحركة اليومية'!D72 -> 43352.4 | D6: ='الحركة اليومية'!E72 -> 196776.1 | E6: ='الحركة اليومية'!F72 -> 37851.2 | F6: ='الحركة اليومية'!G72 -> 11742.5 | G6: ='الحركة اليومية'!H72 -> 0 | H6: ='الحركة اليومية'!I72 -> 0 | I6: ='الحركة اليومية'!J72 -> 5495 | J6: ='الحركة اليومية'!K72 -> 0 | ... P6: ='الحركة اليومية'!Q72 -> 8629.4
A7: مارس 2026 | B7: =P6 -> 8629.4 | C7: ='الحركة اليومية'!D108 -> 78829.66 | D7: ='الحركة اليومية'!E108 -> 431081.59 | E7: ='الحركة اليومية'!F108 -> 66453.4 | F7: ='الحركة اليومية'!G108 -> 22811 | G7: ='الحركة اليومية'!H108 -> 0 | H7: ='الحركة اليومية'!I108 -> 0 | I7: ='الحركة اليومية'!J108 -> 21180 | J7: ='الحركة اليومية'!K108 -> 0 | ... P7: ='الحركة اليومية'!Q108 -> 3991.06
A8: ابريل 2026 | B8: =P7 -> 3991.06 | C8: ='الحركة اليومية'!D143 -> 13242 | D8: ='الحركة اليومية'!E143 -> 66276 | E8: ='الحركة اليومية'!F143 -> 9338 | F8: ='الحركة اليومية'!G143 -> 8423 | G8: ='الحركة اليومية'!H143 -> 0 | H8: ='الحركة اليومية'!I143 -> 0 | I8: ='الحركة اليومية'!J143 -> 3006 | J8: ='الحركة اليومية'!K143 -> 399 | ... P8: ='الحركة اليومية'!Q143 -> 3713.06 | Q8: ='الحركة اليومية'!S143 -> 0
A9: مايو 2026 | B9: =P8 -> 3713.06 | C9: ='الحركة اليومية'!D179 -> 15983 | D9: ='الحركة اليومية'!E179 -> 104399.01 | E9: ='الحركة اليومية'!F179 -> 16666 | F9: ='الحركة اليومية'!G179 -> 5301 | G9: ='الحركة اليومية'!H179 -> 0 | H9: ='الحركة اليومية'!I179 -> 0 | I9: ='الحركة اليومية'!J179 -> 4112 | J9: ='الحركة اليومية'!K179 -> 0 | ... P9: ='الحركة اليومية'!Q179 -> 4196.06 | Q9: ='الحركة اليومية'!S179 -> 0
A10: يونيو 2026 | B10: =P9 -> 4196.06 | C10: ='الحركة اليومية'!D214 -> 13357.25 | D10: ='الحركة اليومية'!E214 -> 54610.75 | E10: ='الحركة اليومية'!F214 -> 6466.86 | F10: ='الحركة اليومية'!G214 -> 2486 | G10: ='الحركة اليومية'!H214 -> 0 | H10: ='الحركة اليومية'!I214 -> 0 | I10: ='الحركة اليومية'!J214 -> 1638 | J10: ='الحركة اليومية'!K214 -> 0 | ... P10: ='الحركة اليومية'!Q214 -> 4803.31 | Q10: ='الحركة اليومية'!$S$214 -> 0
A11: يوليو 2026 | B11: =P10 -> 4803.31 | C11: ='الحركة اليومية'!D250 -> 20763.75 | D11: ='الحركة اليومية'!E250 -> 101418.25 | E11: ='الحركة اليومية'!F250 -> 22569.5 | F11: ='الحركة اليومية'!G250 -> 8523 | G11: ='الحركة اليومية'!H250 -> 0 | H11: ='الحركة اليومية'!I250 -> 0 | I11: ='الحركة اليومية'!J250 -> 6566 | J11: ='الحركة اليومية'!K250 -> 0 | ... P11: ='الحركة اليومية'!Q250 -> 1867.06 | Q11: ='الحركة اليومية'!$S$250 -> 0
A12: اغسطس 2026 | B12: =P11 -> 1867.06 | C12: ='الحركة اليومية'!D286 -> 22711 | D12: ='الحركة اليومية'!E286 -> 187195.5 | E12: ='الحركة اليومية'!F286 -> 26249.5 | F12: ='الحركة اليومية'!G286 -> 8484 | G12: ='الحركة اليومية'!H286 -> 0 | H12: ='الحركة اليومية'!I286 -> 0 | I12: ='الحركة اليومية'!J286 -> 12775.5 | J12: ='الحركة اليومية'!K286 -> 0 | ... P12: ='الحركة اليومية'!Q286 -> 2806.56 | Q12: ='الحركة اليومية'!S286 -> 0
A13: سبتمبر 2026 | B13: =P12 -> 2806.56 | C13: ='الحركة اليومية'!D321 -> 10323 | D13: ='الحركة اليومية'!E321 -> 63904 | E13: ='الحركة اليومية'!F321 -> 8711 | F13: ='الحركة اليومية'!G321 -> 2557 | G13: ='الحركة اليومية'!H321 -> 0 | H13: ='الحركة اليومية'!I321 -> 0 | I13: ='الحركة اليومية'!J321 -> 1682 | J13: ='الحركة اليومية'!K321 -> 0 | ... P13: ='الحركة اليومية'!Q321 -> 8129.56
A14: اكتوبر 2026 | B14: =P13 -> 8129.56 | C14: ='الحركة اليومية'!D357 -> 0 | D14: ='الحركة اليومية'!E357 -> 0 | E14: ='الحركة اليومية'!F357 -> 0 | F14: ='الحركة اليومية'!G357 -> 0 | G14: ='الحركة اليومية'!H357 -> 0 | H14: ='الحركة اليومية'!I357 -> 0 | I14: ='الحركة اليومية'!J357 -> 0 | J14: ='الحركة اليومية'!K357 -> 0 | ... P14: ='الحركة اليومية'!Q357 -> 8129.56 | Q14: ='الحركة اليومية'!$S$357 -> 0
A15: نوفمبر 2026 | B15: =P14 -> 8129.56 | C15: ='الحركة اليومية'!D392 -> 0 | D15: ='الحركة اليومية'!E392 -> 0 | E15: ='الحركة اليومية'!F392 -> 0 | F15: ='الحركة اليومية'!G392 -> 0 | G15: ='الحركة اليومية'!H392 -> 0 | H15: ='الحركة اليومية'!I392 -> 0 | I15: ='الحركة اليومية'!J392 -> 0 | J15: ='الحركة اليومية'!K392 -> 0 | ... P15: ='الحركة اليومية'!Q392 -> 8129.56 | Q15: ='الحركة اليومية'!S392 -> 0
A16: ديسمبر 2026 | B16: =P15 -> 8129.56 | C16: ='الحركة اليومية'!D428 -> 0 | D16: ='الحركة اليومية'!E428 -> 0 | E16: ='الحركة اليومية'!F428 -> 0 | F16: ='الحركة اليومية'!G428 -> 0 | G16: ='الحركة اليومية'!H428 -> 0 | H16: ='الحركة اليومية'!I428 -> 0 | I16: ='الحركة اليومية'!J428 -> 0 | J16: ='الحركة اليومية'!K428 -> 0 | ... P16: ='الحركة اليومية'!Q428 -> 8129.56 | Q16: ='الحركة اليومية'!S428 -> 0
B19: =P19 -> 0 | C19: ='الحركة اليومية'!D434 -> 244689.06 | D19: ='الحركة اليومية'!E434 -> 1325530.2 | E19: ='الحركة اليومية'!F434 -> 208839.46 | F19: ='الحركة اليومية'!G434 -> 75957.5 | G19: ='الحركة اليومية'!H434 -> 22 | H19: ='الحركة اليومية'!I434 -> 0 | J19: ='الحركة اليومية'!K434 -> 399 | K19: ='الحركة اليومية'!L434 -> 1916995.7 | L19: ='الحركة اليومية'!M434 -> 233350 | M19: ='الحركة اليومية'!N434 -> 1610349.2 | N19: ='الحركة اليومية'!O434 -> 61957.5 | O19: ='الحركة اليومية'!P434 -> 3209.5 | P19: ='الحركة اليومية'!Q434 -> 0 | Q19: ='الحركة اليومية'!S434 -> 0

Sheet التعليمـــــــــــــات
B2: عزيزي / مدير المعرض
B4: نامل التقيد بالتعليمات التالية والخاصة بالادارة المالية
A6: 1 | B6: النقد الموجود نتيجة المبيعات هو عهدة على مدير المعرض ونائبة لحين ايداعه بحساب الشركة الرسمي
A7: 2 | B7: لا يسمح اطلاقا تسليم اي موظف بالشركة ايا كانت وظيفته اي مبلغ نقدي وملزم مدير المعرض بهذه المبالغ في حال تجاوزه للتعليمات
A8: 3 | B8: التقيد التام بتسجيل المبيعات بشكل يومي وارسال الملف للادارة المالية بنهاية كل يوم او بداية اليوم التالي
A9: 4 | B9: التقيد بتسجيل رقم الايداع بشكل متسلسل ليتم الوصول ومراجعة اي ايداع بشكل متسلسل ( عمود رقم تسلسل الايداع )
A10: 5 | B10: التقيد بارسال حركة الموازنة ضمن حركة ارسال ملف المبيعات
A11: 6 | B11: التقيد بارسال حركة الموازنة شريطة ان تكون متوازنة
A12: 7 | B12: التقيد بارسال فواتير المشتريات بشكل منتظم اسبوعيا
A13: 8 | B13: التقيد بمطابقة المبيعات بشكل يومي وبنهاية كل اسبوع وبنهاية كل شهر وتصحيح الفرق ان وجد واطلاع الادارة على التعديل
A14: 9 | B14: يمنع منعا بات تعديل اي بيانات لحركة المبيعات لشهر سابق تم اعتماده مسبقا
A15: 10 | B15: يمنع صرف اي بضاعة من المعرض الا بموجب مستند رسمي ( مرتجع للمورد او طلب عينات )
A16: 11 | B16: يمنع ادخال اي بضاعة الى المعرض الا بموجب فاتورة رسمية مقترنة بامرالشراء
A17: 12 | B17: يتم استلام امر الشراء حسب الكمية الورادة فعليا
